Workbook

Sheet ①使い方
A1: 中位60%アップセル機会表（福田会計・営業C-1既存）
A2: 作成日: 2026-07-18 ／ 基準: LTV測定v1（税務顧問171件・契約報酬合計7,253万円・上位20%(35件)で売上46%）
A4: ■ 目的
A5: 中位60%層（LTV測定v1では約103先）に対し、+10万円/社のアップセル機会を可視化し、提案先と提案商品を確定する。
A7: ■ 使い方（3ステップ）
A8: STEP1: シート②の黄色セル「年間契約報酬」に、MJS/マネーフォワードの契約データから年間報酬（税抜・円）を転記する。
A9: → 入力すると「層判定」（上位20%／中位60%／下位20%）が自動計算される。
A10: STEP2: 層判定が「中位60%」の先について、戦略整合性チェック①〜⑥（該当=1、非該当=0）を入力する。
A11: → 整合性（高/中/低）と優先度スコアが自動計算される。「◎」列は記帳代行・関与レベルからの自動候補。
A12: STEP3: 優先度スコアの高い先から「提案商品（確定）」「提案額」を入力し、担当者と次アクションを決める。
A13: → シート③に層別集計・担当者別件数・増収ポテンシャルが自動集計される。
A15: ■ 凡例
... A35: ・層判定は「税務顧問対象=1かつ報酬入力済み」の先だけを母集団として毎回再計算される（件数が171件と一致しなくても機能する）。

Sheet ②顧問先マスター
A1: 顧問先マスター＆アップセル判定表
A2: 黄色=入力欄 ／ 青字=事前設定(修正可) ／ 黒字=自動計算。行4は入力例（集計対象外）。
A3: コード | B3: 顧問先名称 | C3: 区分 | D3: 決算月 | E3: 主担当者 | F3: 記帳代行 | G3: 関与レベル | H3: 税務顧問対象 (1/0) | I3: 年間契約報酬 (円・税抜) | J3: 有効 | K3: 報酬順位 | L3: 層判定 | M3: 経理コンサル 候補 | N3: 伴走型 候補 | O3: クラウド創業 候補(手入力○) | P3: コンパクト相続 候補(手入力○) | Q3: チェック① クラウド | R3: チェック② 創業5年 | S3: チェック③ 相続承継 | T3: チェック④ 経理課題 | U3: チェック⑤ DX | V3: チェック⑥ 伴走 | W3: 戦略整合性 | X3: 優先度スコア | Y3: 提案商品 （確定） | Z3: 提案額 (円) | AA3: 次アクション | AB3: ステータス
A4: (例)10999999 | B4: 株式会社サンプル商事 | C4: 法人 | D4: 3 | E4: 福田 秀幸 | F4: あり | G4: C:総勘定元帳の記帳から決算、申告、税務代理まで | H4: 0 | I4: 660000 | J4: 0 | K4: — | L4: (例)中位60% | M4: ◎ | O4: ○ | Q4: 1 | R4: 0 | S4: 0 | T4: 1 | U4: 1 | V4: 1 | W4: 高 | X4: 5 | Y4: 経理コンサル | Z4: 100000 | AA4: 8月面談で経理体制ヒアリング | AB4: 提案準備中
A5: 10100002 | B5: 株式会社 お茶のうちだ | C5: 法人 | D5: 1 | E5: 荻原 真之 | F5: あり | G5: A:伝票作成から決算、申告、税務代理まで | H5: 1 | J5: =IF(AND(H5=1,N(I5)>0),1,0) -> 0 | K5: =IF(J5=1,SUMPRODUCT(($J$5:$J$312=1)*(N($I$5:$I$312)>N(I5)))+1,"") | L5: =IF(J5<>1,"",IF(K5<=ROUND(SUM($J$5:$J$312)*0.2,0),"上位20%",IF(K5<=ROUND(SUM($J$5:$J$312)*0.8,0),"中位60%","下位20%"))) | M5: =IF(F5="あり","◎","") -> ◎ | N5: =IF(OR(LEFT(G5,1)="A",LEFT(G5,1)="B"),"◎","") -> ◎ | W5: =IF((N(Q5)+N(R5)+N(S5)+N(T5)+N(U5)+N(V5))=0,"",IF(AND((N(Q5)+N(R5)+N(T5))>=2,(N(Q5)+N(R5)+N(S5)+N(T5)+N(U5)+N(V5))>=4),"高",IF(AND((N(Q5)+N(R5)+N(T5))>=1,(N(Q5)+N(R5)+N(S5)+N(T5)+N(U5)+N(V5))=3),"中","低"))) | X5: =IF(L5="中位60%",IF(W5="高",3,IF(W5="中",2,IF(W5="低",1,0)))+IF(M5="◎",1,0)+IF(N5="◎",1,0)+IF(O5="○",1,0)+IF(P5="○",1,0),"")
A6: 10100008 | B6: 株式会社 アルファライフ | C6: 法人 | D6: 1 | E6: 福田 純夫 | F6: なし | H6: 1 | J6: =IF(AND(H6=1,N(I6)>0),1,0) -> 0 | K6: =IF(J6=1,SUMPRODUCT(($J$5:$J$312=1)*(N($I$5:$I$312)>N(I6)))+1,"") | L6: =IF(J6<>1,"",IF(K6<=ROUND(SUM($J$5:$J$312)*0.2,0),"上位20%",IF(K6<=ROUND(SUM($J$5:$J$312)*0.8,0),"中位60%","下位20%"))) | M6: =IF(F6="あり","◎","") | N6: =IF(OR(LEFT(G6,1)="A",LEFT(G6,1)="B"),"◎","") | W6: =IF((N(Q6)+N(R6)+N(S6)+N(T6)+N(U6)+N(V6))=0,"",IF(AND((N(Q6)+N(R6)+N(T6))>=2,(N(Q6)+N(R6)+N(S6)+N(T6)+N(U6)+N(V6))>=4),"高",IF(AND((N(Q6)+N(R6)+N(T6))>=1,(N(Q6)+N(R6)+N(S6)+N(T6)+N(U6)+N(V6))=3),"中","低"))) | X6: =IF(L6="中位60%",IF(W6="高",3,IF(W6="中",2,IF(W6="低",1,0)))+IF(M6="◎",1,0)+IF(N6="◎",1,0)+IF(O6="○",1,0)+IF(P6="○",1,0),"")
A7: 10200004 | B7: 株式会社 横島園 | C7: 法人 | D7: 2 | E7: 田村 未帆 | F7: あり | G7: C:総勘定元帳の記帳から決算、申告、税務代理まで | H7: 1 | J7: =IF(AND(H7=1,N(I7)>0),1,0) -> 0 | K7: =IF(J7=1,SUMPRODUCT(($J$5:$J$312=1)*(N($I$5:$I$312)>N(I7)))+1,"") | L7: =IF(J7<>1,"",IF(K7<=ROUND(SUM($J$5:$J$312)*0.2,0),"上位20%",IF(K7<=ROUND(SUM($J$5:$J$312)*0.8,0),"中位60%","下位20%"))) | M7: =IF(F7="あり","◎","") -> ◎ | N7: =IF(OR(LEFT(G7,1)="A",LEFT(G7,1)="B"),"◎","") | W7: =IF((N(Q7)+N(R7)+N(S7)+N(T7)+N(U7)+N(V7))=0,"",IF(AND((N(Q7)+N(R7)+N(T7))>=2,(N(Q7)+N(R7)+N(S7)+N(T7)+N(U7)+N(V7))>=4),"高",IF(AND((N(Q7)+N(R7)+N(T7))>=1,(N(Q7)+N(R7)+N(S7)+N(T7)+N(U7)+N(V7))=3),"中","低"))) | X7: =IF(L7="中位60%",IF(W7="高",3,IF(W7="中",2,IF(W7="低",1,0)))+IF(M7="◎",1,0)+IF(N7="◎",1,0)+IF(O7="○",1,0)+IF(P7="○",1,0),"")
A8: 10200006 | B8: 株式会社 山策 | C8: 法人 | D8: 2 | E8: 福田 純夫 | F8: なし | G8: C:総勘定元帳の記帳から決算、申告、税務代理まで | H8: 1 | J8: =IF(AND(H8=1,N(I8)>0),1,0) -> 0 | K8: =IF(J8=1,SUMPRODUCT(($J$5:$J$312=1)*(N($I$5:$I$312)>N(I8)))+1,"") | L8: =IF(J8<>1,"",IF(K8<=ROUND(SUM($J$5:$J$312)*0.2,0),"上位20%",IF(K8<=ROUND(SUM($J$5:$J$312)*0.8,0),"中位60%","下位20%"))) | M8: =IF(F8="あり","◎","") | N8: =IF(OR(LEFT(G8,1)="A",LEFT(G8,1)="B"),"◎","") | W8: =IF((N(Q8)+N(R8)+N(S8)+N(T8)+N(U8)+N(V8))=0,"",IF(AND((N(Q8)+N(R8)+N(T8))>=2,(N(Q8)+N(R8)+N(S8)+N(T8)+N(U8)+N(V8))>=4),"高",IF(AND((N(Q8)+N(R8)+N(T8))>=1,(N(Q8)+N(R8)+N(S8)+N(T8)+N(U8)+N(V8))=3),"中","低"))) | X8: =IF(L8="中位60%",IF(W8="高",3,IF(W8="中",2,IF(W8="低",1,0)))+IF(M8="◎",1,0)+IF(N8="◎",1,0)+IF(O8="○",1,0)+IF(P8="○",1,0),"")
A9: 10200007 | B9: 株式会社 創造生活 | C9: 法人 | D9: 7 | E9: 福田 秀幸 | F9: あり | G9: D:決算書の作成から申告、税務代理まで | H9: 1 | J9: =IF(AND(H9=1,N(I9)>0),1,0) -> 0 | K9: =IF(J9=1,SUMPRODUCT(($J$5:$J$312=1)*(N($I$5:$I$312)>N(I9)))+1,"") | L9: =IF(J9<>1,"",IF(K9<=ROUND(SUM($J$5:$J$312)*0.2,0),"上位20%",IF(K9<=ROUND(SUM($J$5:$J$312)*0.8,0),"中位60%","下位20%"))) | M9: =IF(F9="あり","◎","") -> ◎ | N9: =IF(OR(LEFT(G9,1)="A",LEFT(G9,1)="B"),"◎","") | W9: =IF((N(Q9)+N(R9)+N(S9)+N(T9)+N(U9)+N(V9))=0,"",IF(AND((N(Q9)+N(R9)+N(T9))>=2,(N(Q9)+N(R9)+N(S9)+N(T9)+N(U9)+N(V9))>=4),"高",IF(AND((N(Q9)+N(R9)+N(T9))>=1,(N(Q9)+N(R9)+N(S9)+N(T9)+N(U9)+N(V9))=3),"中","低"))) | X9: =IF(L9="中位60%",IF(W9="高",3,IF(W9="中",2,IF(W9="低",1,0)))+IF(M9="◎",1,0)+IF(N9="◎",1,0)+IF(O9="○",1,0)+IF(P9="○",1,0),"")
A10: 10200010 | B10: 有限会社 玉木製作所 | C10: 法人 | D10: 2 | E10: 越沼 浩美 | F10: なし | G10: A:伝票作成から決算、申告、税務代理まで | H10: 1 | J10: =IF(AND(H10=1,N(I10)>0),1,0) -> 0 | K10: =IF(J10=1,SUMPRODUCT(($J$5:$J$312=1)*(N($I$5:$I$312)>N(I10)))+1,"") | L10: =IF(J10<>1,"",IF(K10<=ROUND(SUM($J$5:$J$312)*0.2,0),"上位20%",IF(K10<=ROUND(SUM($J$5:$J$312)*0.8,0),"中位60%","下位20%"))) | M10: =IF(F10="あり","◎","") | N10: =IF(OR(LEFT(G10,1)="A",LEFT(G10,1)="B"),"◎","") -> ◎ | W10: =IF((N(Q10)+N(R10)+N(S10)+N(T10)+N(U10)+N(V10))=0,"",IF(AND((N(Q10)+N(R10)+N(T10))>=2,(N(Q10)+N(R10)+N(S10)+N(T10)+N(U10)+N(V10))>=4),"高",IF(AND((N(Q10)+N(R10)+N(T10))>=1,(N(Q10)+N(R10)+N(S10)+N(T10)+N(U10)+N(V10))=3),"中","低"))) | X10: =IF(L10="中位60%",IF(W10="高",3,IF(W10="中",2,IF(W10="低",1,0)))+IF(M10="◎",1,0)+IF(N10="◎",1,0)+IF(O10="○",1,0)+IF(P10="○",1,0),"")
A11: 10200013 | B11: 株式会社 東洋企画 | C11: 法人 | D11: 2 | E11: 和田 小百合 | F11: あり | H11: 1 | J11: =IF(AND(H11=1,N(I11)>0),1,0) -> 0 | K11: =IF(J11=1,SUMPRODUCT(($J$5:$J$312=1)*(N($I$5:$I$312)>N(I11)))+1,"") | L11: =IF(J11<>1,"",IF(K11<=ROUND(SUM($J$5:$J$312)*0.2,0),"上位20%",IF(K11<=ROUND(SUM($J$5:$J$312)*0.8,0),"中位60%","下位20%"))) | M11: =IF(F11="あり","◎","") -> ◎ | N11: =IF(OR(LEFT(G11,1)="A",LEFT(G11,1)="B"),"◎","") | W11: =IF((N(Q11)+N(R11)+N(S11)+N(T11)+N(U11)+N(V11))=0,"",IF(AND((N(Q11)+N(R11)+N(T11))>=2,(N(Q11)+N(R11)+N(S11)+N(T11)+N(U11)+N(V11))>=4),"高",IF(AND((N(Q11)+N(R11)+N(T11))>=1,(N(Q11)+N(R11)+N(S11)+N(T11)+N(U11)+N(V11))=3),"中","低"))) | X11: =IF(L11="中位60%",IF(W11="高",3,IF(W11="中",2,IF(W11="低",1,0)))+IF(M11="◎",1,0)+IF(N11="◎",1,0)+IF(O11="○",1,0)+IF(P11="○",1,0),"")
A12: 10200015 | B12: 株式会社 ナノグラスコーティング | C12: 法人 | D12: 2 | E12: 福田 純夫 | F12: なし | H12: 1 | J12: =IF(AND(H12=1,N(I12)>0),1,0) -> 0 | K12: =IF(J12=1,SUMPRODUCT(($J$5:$J$312=1)*(N($I$5:$I$312)>N(I12)))+1,"") | L12: =IF(J12<>1,"",IF(K12<=ROUND(SUM($J$5:$J$312)*0.2,0),"上位20%",IF(K12<=ROUND(SUM($J$5:$J$312)*0.8,0),"中位60%","下位20%"))) | M12: =IF(F12="あり","◎","") | N12: =IF(OR(LEFT(G12,1)="A",LEFT(G12,1)="B"),"◎","") | W12: =IF((N(Q12)+N(R12)+N(S12)+N(T12)+N(U12)+N(V12))=0,"",IF(AND((N(Q12)+N(R12)+N(T12))>=2,(N(Q12)+N(R12)+N(S12)+N(T12)+N(U12)+N(V12))>=4),"高",IF(AND((N(Q12)+N(R12)+N(T12))>=1,(N(Q12)+N(R12)+N(S12)+N(T12)+N(U12)+N(V12))=3),"中","低"))) | X12: =IF(L12="中位60%",IF(W12="高",3,IF(W12="中",2,IF(W12="低",1,0)))+IF(M12="◎",1,0)+IF(N12="◎",1,0)+IF(O12="○",1,0)+IF(P12="○",1,0),"")
A13: 10200016 | B13: 株式会社 トップ・アシスト | C13: 法人 | D13: 2 | E13: 和田 小百合 | F13: あり | H13: 1 | J13: =IF(AND(H13=1,N(I13)>0),1,0) -> 0 | K13: =IF(J13=1,SUMPRODUCT(($J$5:$J$312=1)*(N($I$5:$I$312)>N(I13)))+1,"") | L13: =IF(J13<>1,"",IF(K13<=ROUND(SUM($J$5:$J$312)*0.2,0),"上位20%",IF(K13<=ROUND(SUM($J$5:$J$312)*0.8,0),"中位60%","下位20%"))) | M13: =IF(F13="あり","◎","") -> ◎ | N13: =IF(OR(LEFT(G13,1)="A",LEFT(G13,1)="B"),"◎","") | W13: =IF((N(Q13)+N(R13)+N(S13)+N(T13)+N(U13)+N(V13))=0,"",IF(AND((N(Q13)+N(R13)+N(T13))>=2,(N(Q13)+N(R13)+N(S13)+N(T13)+N(U13)+N(V13))>=4),"高",IF(AND((N(Q13)+N(R13)+N(T13))>=1,(N(Q13)+N(R13)+N(S13)+N(T13)+N(U13)+N(V13))=3),"中","低"))) | X13: =IF(L13="中位60%",IF(W13="高",3,IF(W13="中",2,IF(W13="低",1,0)))+IF(M13="◎",1,0)+IF(N13="◎",1,0)+IF(O13="○",1,0)+IF(P13="○",1,0),"")
A14: 10200017 | B14: ヒルインターナショナル 株式会社 | C14: 法人 | D14: 2 | E14: 松崎 恵 | F14: あり | H14: 1 | J14: =IF(AND(H14=1,N(I14)>0),1,0) -> 0 | K14: =IF(J14=1,SUMPRODUCT(($J$5:$J$312=1)*(N($I$5:$I$312)>N(I14)))+1,"") | L14: =IF(J14<>1,"",IF(K14<=ROUND(SUM($J$5:$J$312)*0.2,0),"上位20%",IF(K14<=ROUND(SUM($J$5:$J$312)*0.8,0),"中位60%","下位20%"))) | M14: =IF(F14="あり","◎","") -> ◎ | N14: =IF(OR(LEFT(G14,1)="A",LEFT(G14,1)="B"),"◎","") | W14: =IF((N(Q14)+N(R14)+N(S14)+N(T14)+N(U14)+N(V14))=0,"",IF(AND((N(Q14)+N(R14)+N(T14))>=2,(N(Q14)+N(R14)+N(S14)+N(T14)+N(U14)+N(V14))>=4),"高",IF(AND((N(Q14)+N(R14)+N(T14))>=1,(N(Q14)+N(R14)+N(S14)+N(T14)+N(U14)+N(V14))=3),"中","低"))) | X14: =IF(L14="中位60%",IF(W14="高",3,IF(W14="中",2,IF(W14="低",1,0)))+IF(M14="◎",1,0)+IF(N14="◎",1,0)+IF(O14="○",1,0)+IF(P14="○",1,0),"")
A15: 10300001 | B15: ＣＥＳホールディングス 株式会社 | C15: 法人 | D15: 3 | E15: 荻原 真之 | F15: あり | G15: D:決算書の作成から申告、税務代理まで | H15: 1 | J15: =IF(AND(H15=1,N(I15)>0),1,0) -> 0 | K15: =IF(J15=1,SUMPRODUCT(($J$5:$J$312=1)*(N($I$5:$I$312)>N(I15)))+1,"") | L15: =IF(J15<>1,"",IF(K15<=ROUND(SUM($J$5:$J$312)*0.2,0),"上位20%",IF(K15<=ROUND(SUM($J$5:$J$312)*0.8,0),"中位60%","下位20%"))) | M15: =IF(F15="あり","◎","") -> ◎ | N15: =IF(OR(LEFT(G15,1)="A",LEFT(G15,1)="B"),"◎","") | W15: =IF((N(Q15)+N(R15)+N(S15)+N(T15)+N(U15)+N(V15))=0,"",IF(AND((N(Q15)+N(R15)+N(T15))>=2,(N(Q15)+N(R15)+N(S15)+N(T15)+N(U15)+N(V15))>=4),"高",IF(AND((N(Q15)+N(R15)+N(T15))>=1,(N(Q15)+N(R15)+N(S15)+N(T15)+N(U15)+N(V15))=3),"中","低"))) | X15: =IF(L15="中位60%",IF(W15="高",3,IF(W15="中",2,IF(W15="低",1,0)))+IF(M15="◎",1,0)+IF(N15="◎",1,0)+IF(O15="○",1,0)+IF(P15="○",1,0),"")
A16: 10300004 | B16: コアデザイン 株式会社 | C16: 法人 | D16: 3 | E16: 福田 純夫 | F16: あり | G16: C:総勘定元帳の記帳から決算、申告、税務代理まで | H16: 1 | J16: =IF(AND(H16=1,N(I16)>0),1,0) -> 0 | K16: =IF(J16=1,SUMPRODUCT(($J$5:$J$312=1)*(N($I$5:$I$312)>N(I16)))+1,"") | L16: =IF(J16<>1,"",IF(K16<=ROUND(SUM($J$5:$J$312)*0.2,0),"上位20%",IF(K16<=ROUND(SUM($J$5:$J$312)*0.8,0),"中位60%","下位20%"))) | M16: =IF(F16="あり","◎","") -> ◎ | N16: =IF(OR(LEFT(G16,1)="A",LEFT(G16,1)="B"),"◎","") | W16: =IF((N(Q16)+N(R16)+N(S16)+N(T16)+N(U16)+N(V16))=0,"",IF(AND((N(Q16)+N(R16)+N(T16))>=2,(N(Q16)+N(R16)+N(S16)+N(T16)+N(U16)+N(V16))>=4),"高",IF(AND((N(Q16)+N(R16)+N(T16))>=1,(N(Q16)+N(R16)+N(S16)+N(T16)+N(U16)+N(V16))=3),"中","低"))) | X16: =IF(L16="中位60%",IF(W16="高",3,IF(W16="中",2,IF(W16="低",1,0)))+IF(M16="◎",1,0)+IF(N16="◎",1,0)+IF(O16="○",1,0)+IF(P16="○",1,0),"")
A17: 10300008 | B17: 医療法人 日望会 | C17: 法人 | D17: 3 | E17: 荻原 真之 | F17: なし | G17: A:伝票作成から決算、申告、税務代理まで | H17: 1 | J17: =IF(AND(H17=1,N(I17)>0),1,0) -> 0 | K17: =IF(J17=1,SUMPRODUCT(($J$5:$J$312=1)*(N($I$5:$I$312)>N(I17)))+1,"") | L17: =IF(J17<>1,"",IF(K17<=ROUND(SUM($J$5:$J$312)*0.2,0),"上位20%",IF(K17<=ROUND(SUM($J$5:$J$312)*0.8,0),"中位60%","下位20%"))) | M17: =IF(F17="あり","◎","") | N17: =IF(OR(LEFT(G17,1)="A",LEFT(G17,1)="B"),"◎","") -> ◎ | W17: =IF((N(Q17)+N(R17)+N(S17)+N(T17)+N(U17)+N(V17))=0,"",IF(AND((N(Q17)+N(R17)+N(T17))>=2,(N(Q17)+N(R17)+N(S17)+N(T17)+N(U17)+N(V17))>=4),"高",IF(AND((N(Q17)+N(R17)+N(T17))>=1,(N(Q17)+N(R17)+N(S17)+N(T17)+N(U17)+N(V17))=3),"中","低"))) | X17: =IF(L17="中位60%",IF(W17="高",3,IF(W17="中",2,IF(W17="低",1,0)))+IF(M17="◎",1,0)+IF(N17="◎",1,0)+IF(O17="○",1,0)+IF(P17="○",1,0),"")
A18: 10300010 | B18: 株式会社 ＦＭ桐生 | C18: 法人 | D18: 3 | E18: 荻原 真之 | F18: なし | G18: B:補助簿の記帳から決算、申告、税務代理まで | H18: 1 | J18: =IF(AND(H18=1,N(I18)>0),1,0) -> 0 | K18: =IF(J18=1,SUMPRODUCT(($J$5:$J$312=1)*(N($I$5:$I$312)>N(I18)))+1,"") | L18: =IF(J18<>1,"",IF(K18<=ROUND(SUM($J$5:$J$312)*0.2,0),"上位20%",IF(K18<=ROUND(SUM($J$5:$J$312)*0.8,0),"中位60%","下位20%"))) | M18: =IF(F18="あり","◎","") | N18: =IF(OR(LEFT(G18,1)="A",LEFT(G18,1)="B"),"◎","") -> ◎ | W18: =IF((N(Q18)+N(R18)+N(S18)+N(T18)+N(U18)+N(V18))=0,"",IF(AND((N(Q18)+N(R18)+N(T18))>=2,(N(Q18)+N(R18)+N(S18)+N(T18)+N(U18)+N(V18))>=4),"高",IF(AND((N(Q18)+N(R18)+N(T18))>=1,(N(Q18)+N(R18)+N(S18)+N(T18)+N(U18)+N(V18))=3),"中","低"))) | X18: =IF(L18="中位60%",IF(W18="高",3,IF(W18="中",2,IF(W18="低",1,0)))+IF(M18="◎",1,0)+IF(N18="◎",1,0)+IF(O18="○",1,0)+IF(P18="○",1,0),"")
A19: 10300011 | B19: 株式会社 ｉ４ | C19: 法人 | D19: 3 | E19: 和田 小百合 | F19: あり | G19: B:補助簿の記帳から決算、申告、税務代理まで | H19: 1 | J19: =IF(AND(H19=1,N(I19)>0),1,0) -> 0 | K19: =IF(J19=1,SUMPRODUCT(($J$5:$J$312=1)*(N($I$5:$I$312)>N(I19)))+1,"") | L19: =IF(J19<>1,"",IF(K19<=ROUND(SUM($J$5:$J$312)*0.2,0),"上位20%",IF(K19<=ROUND(SUM($J$5:$J$312)*0.8,0),"中位60%","下位20%"))) | M19: =IF(F19="あり","◎","") -> ◎ | N19: =IF(OR(LEFT(G19,1)="A",LEFT(G19,1)="B"),"◎","") -> ◎ | W19: =IF((N(Q19)+N(R19)+N(S19)+N(T19)+N(U19)+N(V19))=0,"",IF(AND((N(Q19)+N(R19)+N(T19))>=2,(N(Q19)+N(R19)+N(S19)+N(T19)+N(U19)+N(V19))>=4),"高",IF(AND((N(Q19)+N(R19)+N(T19))>=1,(N(Q19)+N(R19)+N(S19)+N(T19)+N(U19)+N(V19))=3),"中","低"))) | X19: =IF(L19="中位60%",IF(W19="高",3,IF(W19="中",2,IF(W19="低",1,0)))+IF(M19="◎",1,0)+IF(N19="◎",1,0)+IF(O19="○",1,0)+IF(P19="○",1,0),"")
A20: 10300012 | B20: 株式会社 ＮＡＮＫＵＲＵ | C20: 法人 | D20: 3 | E20: 福田 純夫 | F20: なし | G20: B:補助簿の記帳から決算、申告、税務代理まで | H20: 1 | J20: =IF(AND(H20=1,N(I20)>0),1,0) -> 0 | K20: =IF(J20=1,SUMPRODUCT(($J$5:$J$312=1)*(N($I$5:$I$312)>N(I20)))+1,"") | L20: =IF(J20<>1,"",IF(K20<=ROUND(SUM($J$5:$J$312)*0.2,0),"上位20%",IF(K20<=ROUND(SUM($J$5:$J$312)*0.8,0),"中位60%","下位20%"))) | M20: =IF(F20="あり","◎","") | N20: =IF(OR(LEFT(G20,1)="A",LEFT(G20,1)="B"),"◎","") -> ◎ | W20: =IF((N(Q20)+N(R20)+N(S20)+N(T20)+N(U20)+N(V20))=0,"",IF(AND((N(Q20)+N(R20)+N(T20))>=2,(N(Q20)+N(R20)+N(S20)+N(T20)+N(U20)+N(V20))>=4),"高",IF(AND((N(Q20)+N(R20)+N(T20))>=1,(N(Q20)+N(R20)+N(S20)+N(T20)+N(U20)+N(V20))=3),"中","低"))) | X20: =IF(L20="中位60%",IF(W20="高",3,IF(W20="中",2,IF(W20="低",1,0)))+IF(M20="◎",1,0)+IF(N20="◎",1,0)+IF(O20="○",1,0)+IF(P20="○",1,0),"")
A21: 10300013 | B21: 株式会社 カネジン | C21: 法人 | D21: 3 | E21: 柳 陽平 | F21: あり | G21: D:決算書の作成から申告、税務代理まで | H21: 1 | J21: =IF(AND(H21=1,N(I21)>0),1,0) -> 0 | K21: =IF(J21=1,SUMPRODUCT(($J$5:$J$312=1)*(N($I$5:$I$312)>N(I21)))+1,"") | L21: =IF(J21<>1,"",IF(K21<=ROUND(SUM($J$5:$J$312)*0.2,0),"上位20%",IF(K21<=ROUND(SUM($J$5:$J$312)*0.8,0),"中位60%","下位20%"))) | M21: =IF(F21="あり","◎","") -> ◎ | N21: =IF(OR(LEFT(G21,1)="A",LEFT(G21,1)="B"),"◎","") | W21: =IF((N(Q21)+N(R21)+N(S21)+N(T21)+N(U21)+N(V21))=0,"",IF(AND((N(Q21)+N(R21)+N(T21))>=2,(N(Q21)+N(R21)+N(S21)+N(T21)+N(U21)+N(V21))>=4),"高",IF(AND((N(Q21)+N(R21)+N(T21))>=1,(N(Q21)+N(R21)+N(S21)+N(T21)+N(U21)+N(V21))=3),"中","低"))) | X21: =IF(L21="中位60%",IF(W21="高",3,IF(W21="中",2,IF(W21="低",1,0)))+IF(M21="◎",1,0)+IF(N21="◎",1,0)+IF(O21="○",1,0)+IF(P21="○",1,0),"")
A22: 10300014 | B22: 株式会社 コメヤ商店 | C22: 法人 | D22: 3 | E22: 松崎 恵 | F22: あり | G22: D:決算書の作成から申告、税務代理まで | H22: 1 | J22: =IF(AND(H22=1,N(I22)>0),1,0) -> 0 | K22: =IF(J22=1,SUMPRODUCT(($J$5:$J$312=1)*(N($I$5:$I$312)>N(I22)))+1,"") | L22: =IF(J22<>1,"",IF(K22<=ROUND(SUM($J$5:$J$312)*0.2,0),"上位20%",IF(K22<=ROUND(SUM($J$5:$J$312)*0.8,0),"中位60%","下位20%"))) | M22: =IF(F22="あり","◎","") -> ◎ | N22: =IF(OR(LEFT(G22,1)="A",LEFT(G22,1)="B"),"◎","") | W22: =IF((N(Q22)+N(R22)+N(S22)+N(T22)+N(U22)+N(V22))=0,"",IF(AND((N(Q22)+N(R22)+N(T22))>=2,(N(Q22)+N(R22)+N(S22)+N(T22)+N(U22)+N(V22))>=4),"高",IF(AND((N(Q22)+N(R22)+N(T22))>=1,(N(Q22)+N(R22)+N(S22)+N(T22)+N(U22)+N(V22))=3),"中","低"))) | X22: =IF(L22="中位60%",IF(W22="高",3,IF(W22="中",2,IF(W22="低",1,0)))+IF(M22="◎",1,0)+IF(N22="◎",1,0)+IF(O22="○",1,0)+IF(P22="○",1,0),"")
A23: 10300015 | B23: 株式会社 ワコー住建 | C23: 法人 | D23: 3 | E23: 柳 陽平 | F23: あり | G23: D:決算書の作成から申告、税務代理まで | H23: 1 | J23: =IF(AND(H23=1,N(I23)>0),1,0) -> 0 | K23: =IF(J23=1,SUMPRODUCT(($J$5:$J$312=1)*(N($I$5:$I$312)>N(I23)))+1,"") | L23: =IF(J23<>1,"",IF(K23<=ROUND(SUM($J$5:$J$312)*0.2,0),"上位20%",IF(K23<=ROUND(SUM($J$5:$J$312)*0.8,0),"中位60%","下位20%"))) | M23: =IF(F23="あり","◎","") -> ◎ | N23: =IF(OR(LEFT(G23,1)="A",LEFT(G23,1)="B"),"◎","") | W23: =IF((N(Q23)+N(R23)+N(S23)+N(T23)+N(U23)+N(V23))=0,"",IF(AND((N(Q23)+N(R23)+N(T23))>=2,(N(Q23)+N(R23)+N(S23)+N(T23)+N(U23)+N(V23))>=4),"高",IF(AND((N(Q23)+N(R23)+N(T23))>=1,(N(Q23)+N(R23)+N(S23)+N(T23)+N(U23)+N(V23))=3),"中","低"))) | X23: =IF(L23="中位60%",IF(W23="高",3,IF(W23="中",2,IF(W23="低",1,0)))+IF(M23="◎",1,0)+IF(N23="◎",1,0)+IF(O23="○",1,0)+IF(P23="○",1,0),"")
A24: 10300017 | B24: 株式会社 Ｇｒｅｅｎ Ｃａｍｐ | C24: 法人 | D24: 3 | E24: 松崎 恵 | F24: あり | G24: C:総勘定元帳の記帳から決算、申告、税務代理まで | H24: 1 | J24: =IF(AND(H24=1,N(I24)>0),1,0) -> 0 | K24: =IF(J24=1,SUMPRODUCT(($J$5:$J$312=1)*(N($I$5:$I$312)>N(I24)))+1,"") | L24: =IF(J24<>1,"",IF(K24<=ROUND(SUM($J$5:$J$312)*0.2,0),"上位20%",IF(K24<=ROUND(SUM($J$5:$J$312)*0.8,0),"中位60%","下位20%"))) | M24: =IF(F24="あり","◎","") -> ◎ | N24: =IF(OR(LEFT(G24,1)="A",LEFT(G24,1)="B"),"◎","") | W24: =IF((N(Q24)+N(R24)+N(S24)+N(T24)+N(U24)+N(V24))=0,"",IF(AND((N(Q24)+N(R24)+N(T24))>=2,(N(Q24)+N(R24)+N(S24)+N(T24)+N(U24)+N(V24))>=4),"高",IF(AND((N(Q24)+N(R24)+N(T24))>=1,(N(Q24)+N(R24)+N(S24)+N(T24)+N(U24)+N(V24))=3),"中","低"))) | X24: =IF(L24="中位60%",IF(W24="高",3,IF(W24="中",2,IF(W24="低",1,0)))+IF(M24="◎",1,0)+IF(N24="◎",1,0)+IF(O24="○",1,0)+IF(P24="○",1,0),"")
A25: 10300018 | B25: 協同組合 川内ガス供給センター | C25: 法人 | D25: 3 | E25: 福田 秀幸 | F25: なし | G25: D:決算書の作成から申告、税務代理まで | H25: 1 | J25: =IF(AND(H25=1,N(I25)>0),1,0) -> 0 | K25: =IF(J25=1,SUMPRODUCT(($J$5:$J$312=1)*(N($I$5:$I$312)>N(I25)))+1,"") | L25: =IF(J25<>1,"",IF(K25<=ROUND(SUM($J$5:$J$312)*0.2,0),"上位20%",IF(K25<=ROUND(SUM($J$5:$J$312)*0.8,0),"中位60%","下位20%"))) | M25: =IF(F25="あり","◎","") | N25: =IF(OR(LEFT(G25,1)="A",LEFT(G25,1)="B"),"◎","") | W25: =IF((N(Q25)+N(R25)+N(S25)+N(T25)+N(U25)+N(V25))=0,"",IF(AND((N(Q25)+N(R25)+N(T25))>=2,(N(Q25)+N(R25)+N(S25)+N(T25)+N(U25)+N(V25))>=4),"高",IF(AND((N(Q25)+N(R25)+N(T25))>=1,(N(Q25)+N(R25)+N(S25)+N(T25)+N(U25)+N(V25))=3),"中","低"))) | X25: =IF(L25="中位60%",IF(W25="高",3,IF(W25="中",2,IF(W25="低",1,0)))+IF(M25="◎",1,0)+IF(N25="◎",1,0)+IF(O25="○",1,0)+IF(P25="○",1,0),"")
A26: 10300019 | B26: 社会福祉法人 有為会 | C26: 法人 | D26: 3 | E26: 福田 秀幸 | F26: なし | G26: D:決算書の作成から申告、税務代理まで | H26: 1 | J26: =IF(AND(H26=1,N(I26)>0),1,0) -> 0 | K26: =IF(J26=1,SUMPRODUCT(($J$5:$J$312=1)*(N($I$5:$I$312)>N(I26)))+1,"") | L26: =IF(J26<>1,"",IF(K26<=ROUND(SUM($J$5:$J$312)*0.2,0),"上位20%",IF(K26<=ROUND(SUM($J$5:$J$312)*0.8,0),"中位60%","下位20%"))) | M26: =IF(F26="あり","◎","") | N26: =IF(OR(LEFT(G26,1)="A",LEFT(G26,1)="B"),"◎","") | W26: =IF((N(Q26)+N(R26)+N(S26)+N(T26)+N(U26)+N(V26))=0,"",IF(AND((N(Q26)+N(R26)+N(T26))>=2,(N(Q26)+N(R26)+N(S26)+N(T26)+N(U26)+N(V26))>=4),"高",IF(AND((N(Q26)+N(R26)+N(T26))>=1,(N(Q26)+N(R26)+N(S26)+N(T26)+N(U26)+N(V26))=3),"中","低"))) | X26: =IF(L26="中位60%",IF(W26="高",3,IF(W26="中",2,IF(W26="低",1,0)))+IF(M26="◎",1,0)+IF(N26="◎",1,0)+IF(O26="○",1,0)+IF(P26="○",1,0),"")
... A31: 10300028 | B31: 地域計画 株式会社 | C31: 法人 | D31: 9 | E31: 松崎 恵 | F31: なし | G31: B:補助簿の記帳から決算、申告、税務代理まで | H31: 1 | J31: =IF(AND(H31=1,N(I31)>0),1,0) -> 0 | K31: =IF(J31=1,SUMPRODUCT(($J$5:$J$312=1)*(N($I$5:$I$312)>N(I31)))+1,"") | L31: =IF(J31<>1,"",IF(K31<=ROUND(SUM($J$5:$J$312)*0.2,0),"上位20%",IF(K31<=ROUND(SUM($J$5:$J$312)*0.8,0),"中位60%","下位20%"))) | M31: =IF(F31="あり","◎","") | N31: =IF(OR(LEFT(G31,1)="A",LEFT(G31,1)="B"),"◎","") -> ◎ | W31: =IF((N(Q31)+N(R31)+N(S31)+N(T31)+N(U31)+N(V31))=0,"",IF(AND((N(Q31)+N(R31)+N(T31))>=2,(N(Q31)+N(R31)+N(S31)+N(T31)+N(U31)+N(V31))>=4),"高",IF(AND((N(Q31)+N(R31)+N(T31))>=1,(N(Q31)+N(R31)+N(S31)+N(T31)+N(U31)+N(V31))=3),"中","低"))) | X31: =IF(L31="中位60%",IF(W31="高",3,IF(W31="中",2,IF(W31="低",1,0)))+IF(M31="◎",1,0)+IF(N31="◎",1,0)+IF(O31="○",1,0)+IF(P31="○",1,0),"")
A32: 10300030 | B32: 株式会社 服飾工房絲 | C32: 法人 | D32: 3 | E32: 越沼 浩美 | F32: あり | H32: 1 | J32: =IF(AND(H32=1,N(I32)>0),1,0) -> 0 | K32: =IF(J32=1,SUMPRODUCT(($J$5:$J$312=1)*(N($I$5:$I$312)>N(I32)))+1,"") | L32: =IF(J32<>1,"",IF(K32<=ROUND(SUM($J$5:$J$312)*0.2,0),"上位20%",IF(K32<=ROUND(SUM($J$5:$J$312)*0.8,0),"中位60%","下位20%"))) | M32: =IF(F32="あり","◎","") -> ◎ | N32: =IF(OR(LEFT(G32,1)="A",LEFT(G32,1)="B"),"◎","") | W32: =IF((N(Q32)+N(R32)+N(S32)+N(T32)+N(U32)+N(V32))=0,"",IF(AND((N(Q32)+N(R32)+N(T32))>=2,(N(Q32)+N(R32)+N(S32)+N(T32)+N(U32)+N(V32))>=4),"高",IF(AND((N(Q32)+N(R32)+N(T32))>=1,(N(Q32)+N(R32)+N(S32)+N(T32)+N(U32)+N(V32))=3),"中","低"))) | X32: =IF(L32="中位60%",IF(W32="高",3,IF(W32="中",2,IF(W32="低",1,0)))+IF(M32="◎",1,0)+IF(N32="◎",1,0)+IF(O32="○",1,0)+IF(P32="○",1,0),"")
A33: 10300031 | B33: Ｌｉｋｅ Ｄｍ 株式会社 | C33: 法人 | D33: 3 | E33: 田村 未帆 | F33: あり | G33: C:総勘定元帳の記帳から決算、申告、税務代理まで | H33: 1 | J33: =IF(AND(H33=1,N(I33)>0),1,0) -> 0 | K33: =IF(J33=1,SUMPRODUCT(($J$5:$J$312=1)*(N($I$5:$I$312)>N(I33)))+1,"") | L33: =IF(J33<>1,"",IF(K33<=ROUND(SUM($J$5:$J$312)*0.2,0),"上位20%",IF(K33<=ROUND(SUM($J$5:$J$312)*0.8,0),"中位60%","下位20%"))) | M33: =IF(F33="あり","◎","") -> ◎ | N33: =IF(OR(LEFT(G33,1)="A",LEFT(G33,1)="B"),"◎","") | W33: =IF((N(Q33)+N(R33)+N(S33)+N(T33)+N(U33)+N(V33))=0,"",IF(AND((N(Q33)+N(R33)+N(T33))>=2,(N(Q33)+N(R33)+N(S33)+N(T33)+N(U33)+N(V33))>=4),"高",IF(AND((N(Q33)+N(R33)+N(T33))>=1,(N(Q33)+N(R33)+N(S33)+N(T33)+N(U33)+N(V33))=3),"中","低"))) | X33: =IF(L33="中位60%",IF(W33="高",3,IF(W33="中",2,IF(W33="低",1,0)))+IF(M33="◎",1,0)+IF(N33="◎",1,0)+IF(O33="○",1,0)+IF(P33="○",1,0),"")
A34: 10300032 | B34: 株式会社 恭 | C34: 法人 | D34: 3 | E34: 松崎 恵 | F34: あり | G34: A:伝票作成から決算、申告、税務代理まで | H34: 1 | J34: =IF(AND(H34=1,N(I34)>0),1,0) -> 0 | K34: =IF(J34=1,SUMPRODUCT(($J$5:$J$312=1)*(N($I$5:$I$312)>N(I34)))+1,"") | L34: =IF(J34<>1,"",IF(K34<=ROUND(SUM($J$5:$J$312)*0.2,0),"上位20%",IF(K34<=ROUND(SUM($J$5:$J$312)*0.8,0),"中位60%","下位20%"))) | M34: =IF(F34="あり","◎","") -> ◎ | N34: =IF(OR(LEFT(G34,1)="A",LEFT(G34,1)="B"),"◎","") -> ◎ | W34: =IF((N(Q34)+N(R34)+N(S34)+N(T34)+N(U34)+N(V34))=0,"",IF(AND((N(Q34)+N(R34)+N(T34))>=2,(N(Q34)+N(R34)+N(S34)+N(T34)+N(U34)+N(V34))>=4),"高",IF(AND((N(Q34)+N(R34)+N(T34))>=1,(N(Q34)+N(R34)+N(S34)+N(T34)+N(U34)+N(V34))=3),"中","低"))) | X34: =IF(L34="中位60%",IF(W34="高",3,IF(W34="中",2,IF(W34="低",1,0)))+IF(M34="◎",1,0)+IF(N34="◎",1,0)+IF(O34="○",1,0)+IF(P34="○",1,0),"")
A35: 10300037 | B35: 一般社団法人 ＭｉＬＫＹ ＷＡＹ | C35: 法人 | D35: 3 | E35: 和田 小百合 | F35: あり | H35: 1 | J35: =IF(AND(H35=1,N(I35)>0),1,0) -> 0 | K35: =IF(J35=1,SUMPRODUCT(($J$5:$J$312=1)*(N($I$5:$I$312)>N(I35)))+1,"") | L35: =IF(J35<>1,"",IF(K35<=ROUND(SUM($J$5:$J$312)*0.2,0),"上位20%",IF(K35<=ROUND(SUM($J$5:$J$312)*0.8,0),"中位60%","下位20%"))) | M35: =IF(F35="あり","◎","") -> ◎ | N35: =IF(OR(LEFT(G35,1)="A",LEFT(G35,1)="B"),"◎","") | W35: =IF((N(Q35)+N(R35)+N(S35)+N(T35)+N(U35)+N(V35))=0,"",IF(AND((N(Q35)+N(R35)+N(T35))>=2,(N(Q35)+N(R35)+N(S35)+N(T35)+N(U35)+N(V35))>=4),"高",IF(AND((N(Q35)+N(R35)+N(T35))>=1,(N(Q35)+N(R35)+N(S35)+N(T35)+N(U35)+N(V35))=3),"中","低"))) | X35: =IF(L35="中位60%",IF(W35="高",3,IF(W35="中",2,IF(W35="低",1,0)))+IF(M35="◎",1,0)+IF(N35="◎",1,0)+IF(O35="○",1,0)+IF(P35="○",1,0),"")
A36: 10300042 | B36: 特定非営利活動法人 ソンリッサ | C36: 法人 | D36: 3 | E36: 田村 未帆 | F36: あり | H36: 1 | J36: =IF(AND(H36=1,N(I36)>0),1,0) -> 0 | K36: =IF(J36=1,SUMPRODUCT(($J$5:$J$312=1)*(N($I$5:$I$312)>N(I36)))+1,"") | L36: =IF(J36<>1,"",IF(K36<=ROUND(SUM($J$5:$J$312)*0.2,0),"上位20%",IF(K36<=ROUND(SUM($J$5:$J$312)*0.8,0),"中位60%","下位20%"))) | M36: =IF(F36="あり","◎","") -> ◎ | N36: =IF(OR(LEFT(G36,1)="A",LEFT(G36,1)="B"),"◎","") | W36: =IF((N(Q36)+N(R36)+N(S36)+N(T36)+N(U36)+N(V36))=0,"",IF(AND((N(Q36)+N(R36)+N(T36))>=2,(N(Q36)+N(R36)+N(S36)+N(T36)+N(U36)+N(V36))>=4),"高",IF(AND((N(Q36)+N(R36)+N(T36))>=1,(N(Q36)+N(R36)+N(S36)+N(T36)+N(U36)+N(V36))=3),"中","低"))) | X36: =IF(L36="中位60%",IF(W36="高",3,IF(W36="中",2,IF(W36="低",1,0)))+IF(M36="◎",1,0)+IF(N36="◎",1,0)+IF(O36="○",1,0)+IF(P36="○",1,0),"")
A37: 10300043 | B37: 株式会社 関東贈答 | C37: 法人 | D37: 3 | E37: 福田 純夫 | F37: あり | H37: 1 | J37: =IF(AND(H37=1,N(I37)>0),1,0) -> 0 | K37: =IF(J37=1,SUMPRODUCT(($J$5:$J$312=1)*(N($I$5:$I$312)>N(I37)))+1,"") | L37: =IF(J37<>1,"",IF(K37<=ROUND(SUM($J$5:$J$312)*0.2,0),"上位20%",IF(K37<=ROUND(SUM($J$5:$J$312)*0.8,0),"中位60%","下位20%"))) | M37: =IF(F37="あり","◎","") -> ◎ | N37: =IF(OR(LEFT(G37,1)="A",LEFT(G37,1)="B"),"◎","") | W37: =IF((N(Q37)+N(R37)+N(S37)+N(T37)+N(U37)+N(V37))=0,"",IF(AND((N(Q37)+N(R37)+N(T37))>=2,(N(Q37)+N(R37)+N(S37)+N(T37)+N(U37)+N(V37))>=4),"高",IF(AND((N(Q37)+N(R37)+N(T37))>=1,(N(Q37)+N(R37)+N(S37)+N(T37)+N(U37)+N(V37))=3),"中","低"))) | X37: =IF(L37="中位60%",IF(W37="高",3,IF(W37="中",2,IF(W37="低",1,0)))+IF(M37="◎",1,0)+IF(N37="◎",1,0)+IF(O37="○",1,0)+IF(P37="○",1,0),"")
A38: 10300045 | B38: サーテック 合同会社 | C38: 法人 | D38: 3 | E38: 和田 小百合 | F38: あり | H38: 1 | J38: =IF(AND(H38=1,N(I38)>0),1,0) -> 0 | K38: =IF(J38=1,SUMPRODUCT(($J$5:$J$312=1)*(N($I$5:$I$312)>N(I38)))+1,"") | L38: =IF(J38<>1,"",IF(K38<=ROUND(SUM($J$5:$J$312)*0.2,0),"上位20%",IF(K38<=ROUND(SUM($J$5:$J$312)*0.8,0),"中位60%","下位20%"))) | M38: =IF(F38="あり","◎","") -> ◎ | N38: =IF(OR(LEFT(G38,1)="A",LEFT(G38,1)="B"),"◎","") | W38: =IF((N(Q38)+N(R38)+N(S38)+N(T38)+N(U38)+N(V38))=0,"",IF(AND((N(Q38)+N(R38)+N(T38))>=2,(N(Q38)+N(R38)+N(S38)+N(T38)+N(U38)+N(V38))>=4),"高",IF(AND((N(Q38)+N(R38)+N(T38))>=1,(N(Q38)+N(R38)+N(S38)+N(T38)+N(U38)+N(V38))=3),"中","低"))) | X38: =IF(L38="中位60%",IF(W38="高",3,IF(W38="中",2,IF(W38="低",1,0)))+IF(M38="◎",1,0)+IF(N38="◎",1,0)+IF(O38="○",1,0)+IF(P38="○",1,0),"")
A39: 10300061 | B39: 株式会社 ＺＥＤ | C39: 法人 | D39: 3 | E39: 田村 未帆 | F39: あり | H39: 1 | J39: =IF(AND(H39=1,N(I39)>0),1,0) -> 0 | K39: =IF(J39=1,SUMPRODUCT(($J$5:$J$312=1)*(N($I$5:$I$312)>N(I39)))+1,"") | L39: =IF(J39<>1,"",IF(K39<=ROUND(SUM($J$5:$J$312)*0.2,0),"上位20%",IF(K39<=ROUND(SUM($J$5:$J$312)*0.8,0),"中位60%","下位20%"))) | M39: =IF(F39="あり","◎","") -> ◎ | N39: =IF(OR(LEFT(G39,1)="A",LEFT(G39,1)="B"),"◎","") | W39: =IF((N(Q39)+N(R39)+N(S39)+N(T39)+N(U39)+N(V39))=0,"",IF(AND((N(Q39)+N(R39)+N(T39))>=2,(N(Q39)+N(R39)+N(S39)+N(T39)+N(U39)+N(V39))>=4),"高",IF(AND((N(Q39)+N(R39)+N(T39))>=1,(N(Q39)+N(R39)+N(S39)+N(T39)+N(U39)+N(V39))=3),"中","低"))) | X39: =IF(L39="中位60%",IF(W39="高",3,IF(W39="中",2,IF(W39="低",1,0)))+IF(M39="◎",1,0)+IF(N39="◎",1,0)+IF(O39="○",1,0)+IF(P39="○",1,0),"")
A40: 10400002 | B40: スナガロジスティクス 企業組合 | C40: 法人 | D40: 4 | E40: 福田 秀幸 | F40: なし | G40: D:決算書の作成から申告、税務代理まで | H40: 1 | J40: =IF(AND(H40=1,N(I40)>0),1,0) -> 0 | K40: =IF(J40=1,SUMPRODUCT(($J$5:$J$312=1)*(N($I$5:$I$312)>N(I40)))+1,"") | L40: =IF(J40<>1,"",IF(K40<=ROUND(SUM($J$5:$J$312)*0.2,0),"上位20%",IF(K40<=ROUND(SUM($J$5:$J$312)*0.8,0),"中位60%","下位20%"))) | M40: =IF(F40="あり","◎","") | N40: =IF(OR(LEFT(G40,1)="A",LEFT(G40,1)="B"),"◎","") | W40: =IF((N(Q40)+N(R40)+N(S40)+N(T40)+N(U40)+N(V40))=0,"",IF(AND((N(Q40)+N(R40)+N(T40))>=2,(N(Q40)+N(R40)+N(S40)+N(T40)+N(U40)+N(V40))>=4),"高",IF(AND((N(Q40)+N(R40)+N(T40))>=1,(N(Q40)+N(R40)+N(S40)+N(T40)+N(U40)+N(V40))=3),"中","低"))) | X40: =IF(L40="中位60%",IF(W40="高",3,IF(W40="中",2,IF(W40="低",1,0)))+IF(M40="◎",1,0)+IF(N40="◎",1,0)+IF(O40="○",1,0)+IF(P40="○",1,0),"")
A41: 10400003 | B41: 株式会社 スナガビジネスソリューション | C41: 法人 | D41: 4 | E41: 福田 秀幸 | F41: なし | G41: C:総勘定元帳の記帳から決算、申告、税務代理まで | H41: 1 | J41: =IF(AND(H41=1,N(I41)>0),1,0) -> 0 | K41: =IF(J41=1,SUMPRODUCT(($J$5:$J$312=1)*(N($I$5:$I$312)>N(I41)))+1,"") | L41: =IF(J41<>1,"",IF(K41<=ROUND(SUM($J$5:$J$312)*0.2,0),"上位20%",IF(K41<=ROUND(SUM($J$5:$J$312)*0.8,0),"中位60%","下位20%"))) | M41: =IF(F41="あり","◎","") | N41: =IF(OR(LEFT(G41,1)="A",LEFT(G41,1)="B"),"◎","") | W41: =IF((N(Q41)+N(R41)+N(S41)+N(T41)+N(U41)+N(V41))=0,"",IF(AND((N(Q41)+N(R41)+N(T41))>=2,(N(Q41)+N(R41)+N(S41)+N(T41)+N(U41)+N(V41))>=4),"高",IF(AND((N(Q41)+N(R41)+N(T41))>=1,(N(Q41)+N(R41)+N(S41)+N(T41)+N(U41)+N(V41))=3),"中","低"))) | X41: =IF(L41="中位60%",IF(W41="高",3,IF(W41="中",2,IF(W41="低",1,0)))+IF(M41="◎",1,0)+IF(N41="◎",1,0)+IF(O41="○",1,0)+IF(P41="○",1,0),"")
A42: 10400004 | B42: 栄晃ビルサービス 有限会社 | C42: 法人 | D42: 4 | E42: 福田 純夫 | F42: あり | G42: B:補助簿の記帳から決算、申告、税務代理まで | H42: 1 | J42: =IF(AND(H42=1,N(I42)>0),1,0) -> 0 | K42: =IF(J42=1,SUMPRODUCT(($J$5:$J$312=1)*(N($I$5:$I$312)>N(I42)))+1,"") | L42: =IF(J42<>1,"",IF(K42<=ROUND(SUM($J$5:$J$312)*0.2,0),"上位20%",IF(K42<=ROUND(SUM($J$5:$J$312)*0.8,0),"中位60%","下位20%"))) | M42: =IF(F42="あり","◎","") -> ◎ | N42: =IF(OR(LEFT(G42,1)="A",LEFT(G42,1)="B"),"◎","") -> ◎ | W42: =IF((N(Q42)+N(R42)+N(S42)+N(T42)+N(U42)+N(V42))=0,"",IF(AND((N(Q42)+N(R42)+N(T42))>=2,(N(Q42)+N(R42)+N(S42)+N(T42)+N(U42)+N(V42))>=4),"高",IF(AND((N(Q42)+N(R42)+N(T42))>=1,(N(Q42)+N(R42)+N(S42)+N(T42)+N(U42)+N(V42))=3),"中","低"))) | X42: =IF(L42="中位60%",IF(W42="高",3,IF(W42="中",2,IF(W42="低",1,0)))+IF(M42="◎",1,0)+IF(N42="◎",1,0)+IF(O42="○",1,0)+IF(P42="○",1,0),"")
A43: 10400005 | B43: 株式会社 ＴｒｕｓｔＦａｍ | C43: 法人 | D43: 4 | E43: 田村 未帆 | F43: あり | G43: D:決算書の作成から申告、税務代理まで | H43: 1 | J43: =IF(AND(H43=1,N(I43)>0),1,0) -> 0 | K43: =IF(J43=1,SUMPRODUCT(($J$5:$J$312=1)*(N($I$5:$I$312)>N(I43)))+1,"") | L43: =IF(J43<>1,"",IF(K43<=ROUND(SUM($J$5:$J$312)*0.2,0),"上位20%",IF(K43<=ROUND(SUM($J$5:$J$312)*0.8,0),"中位60%","下位20%"))) | M43: =IF(F43="あり","◎","") -> ◎ | N43: =IF(OR(LEFT(G43,1)="A",LEFT(G43,1)="B"),"◎","") | W43: =IF((N(Q43)+N(R43)+N(S43)+N(T43)+N(U43)+N(V43))=0,"",IF(AND((N(Q43)+N(R43)+N(T43))>=2,(N(Q43)+N(R43)+N(S43)+N(T43)+N(U43)+N(V43))>=4),"高",IF(AND((N(Q43)+N(R43)+N(T43))>=1,(N(Q43)+N(R43)+N(S43)+N(T43)+N(U43)+N(V43))=3),"中","低"))) | X43: =IF(L43="中位60%",IF(W43="高",3,IF(W43="中",2,IF(W43="低",1,0)))+IF(M43="◎",1,0)+IF(N43="◎",1,0)+IF(O43="○",1,0)+IF(P43="○",1,0),"")
A44: 10400006 | B44: 株式会社 ガスビック | C44: 法人 | D44: 4 | E44: 福田 秀幸 | F44: なし | G44: C:総勘定元帳の記帳から決算、申告、税務代理まで | H44: 1 | J44: =IF(AND(H44=1,N(I44)>0),1,0) -> 0 | K44: =IF(J44=1,SUMPRODUCT(($J$5:$J$312=1)*(N($I$5:$I$312)>N(I44)))+1,"") | L44: =IF(J44<>1,"",IF(K44<=ROUND(SUM($J$5:$J$312)*0.2,0),"上位20%",IF(K44<=ROUND(SUM($J$5:$J$312)*0.8,0),"中位60%","下位20%"))) | M44: =IF(F44="あり","◎","") | N44: =IF(OR(LEFT(G44,1)="A",LEFT(G44,1)="B"),"◎","") | W44: =IF((N(Q44)+N(R44)+N(S44)+N(T44)+N(U44)+N(V44))=0,"",IF(AND((N(Q44)+N(R44)+N(T44))>=2,(N(Q44)+N(R44)+N(S44)+N(T44)+N(U44)+N(V44))>=4),"高",IF(AND((N(Q44)+N(R44)+N(T44))>=1,(N(Q44)+N(R44)+N(S44)+N(T44)+N(U44)+N(V44))=3),"中","低"))) | X44: =IF(L44="中位60%",IF(W44="高",3,IF(W44="中",2,IF(W44="低",1,0)))+IF(M44="◎",1,0)+IF(N44="◎",1,0)+IF(O44="○",1,0)+IF(P44="○",1,0),"")
...

Sheet ③集計ダッシュボード
A1: アップセル機会 集計ダッシュボード（自動計算）
A3: ■ 層別サマリー
A4: 層 | B4: 件数 | C4: 報酬合計(円) | D4: 売上構成比
A5: 上位20% | B5: =COUNTIF(②顧問先マスター!$L$5:$L$312,"上位20%") -> 0 | C5: =SUMIFS(②顧問先マスター!$I$5:$I$312,②顧問先マスター!$L$5:$L$312,"上位20%") -> 0 | D5: =IF(SUMPRODUCT(②顧問先マスター!$J$5:$J$312,N(②顧問先マスター!$I$5:$I$312))=0,0,C5/SUMPRODUCT(②顧問先マスター!$J$5:$J$312,N(②顧問先マスター!$I$5:$I$312))) -> 0
A6: 中位60% | B6: =COUNTIF(②顧問先マスター!$L$5:$L$312,"中位60%") -> 0 | C6: =SUMIFS(②顧問先マスター!$I$5:$I$312,②顧問先マスター!$L$5:$L$312,"中位60%") -> 0 | D6: =IF(SUMPRODUCT(②顧問先マスター!$J$5:$J$312,N(②顧問先マスター!$I$5:$I$312))=0,0,C6/SUMPRODUCT(②顧問先マスター!$J$5:$J$312,N(②顧問先マスター!$I$5:$I$312))) -> 0
A7: 下位20% | B7: =COUNTIF(②顧問先マスター!$L$5:$L$312,"下位20%") -> 0 | C7: =SUMIFS(②顧問先マスター!$I$5:$I$312,②顧問先マスター!$L$5:$L$312,"下位20%") -> 0 | D7: =IF(SUMPRODUCT(②顧問先マスター!$J$5:$J$312,N(②顧問先マスター!$I$5:$I$312))=0,0,C7/SUMPRODUCT(②顧問先マスター!$J$5:$J$312,N(②顧問先マスター!$I$5:$I$312))) -> 0
A8: 合計 | B8: =SUM(B5:B7) -> 0 | C8: =SUM(C5:C7) -> 0 | D8: =SUM(D5:D7) -> 0
A10: （参考）LTV測定v1基準値: 税務顧問171件・報酬合計72,530,000円・上位20%(35件)で売上46%（出所: 前セッションLTV測定v1、マネーフォワード契約データ集計）
A12: ■ 中位60%アップセルポテンシャル
A13: 指標 | B13: 値
A14: 中位60%件数 | B14: =COUNTIF(②顧問先マスター!$L$5:$L$312,"中位60%") -> 0
A15: ポテンシャル（+10万円/社の場合） | B15: =B14*100000 -> 0
A16: 個別提案額の入力合計（中位60%） | B16: =SUMIFS(②顧問先マスター!$Z$5:$Z$312,②顧問先マスター!$L$5:$L$312,"中位60%") -> 0
A17: 優先度スコア4以上の先数（最優先アプローチ） | B17: =SUMPRODUCT((N(②顧問先マスター!$X$5:$X$312)>=4)*(②顧問先マスター!$L$5:$L$312="中位60%")) -> 0
A19: ■ 担当者別・中位60%件数／提案額
A20: 主担当者 | B20: 中位60%件数 | C20: 提案額合計(円)
A21: 福田 純夫 | B21: =COUNTIFS(②顧問先マスター!$E$5:$E$312,A21,②顧問先マスター!$L$5:$L$312,"中位60%") -> 0 | C21: =SUMIFS(②顧問先マスター!$Z$5:$Z$312,②顧問先マスター!$E$5:$E$312,A21,②顧問先マスター!$L$5:$L$312,"中位60%") -> 0
A22: 松崎 恵 | B22: =COUNTIFS(②顧問先マスター!$E$5:$E$312,A22,②顧問先マスター!$L$5:$L$312,"中位60%") -> 0 | C22: =SUMIFS(②顧問先マスター!$Z$5:$Z$312,②顧問先マスター!$E$5:$E$312,A22,②顧問先マスター!$L$5:$L$312,"中位60%") -> 0
A23: 荻原 真之 | B23: =COUNTIFS(②顧問先マスター!$E$5:$E$312,A23,②顧問先マスター!$L$5:$L$312,"中位60%") -> 0 | C23: =SUMIFS(②顧問先マスター!$Z$5:$Z$312,②顧問先マスター!$E$5:$E$312,A23,②顧問先マスター!$L$5:$L$312,"中位60%") -> 0
A24: 柳 陽平 | B24: =COUNTIFS(②顧問先マスター!$E$5:$E$312,A24,②顧問先マスター!$L$5:$L$312,"中位60%") -> 0 | C24: =SUMIFS(②顧問先マスター!$Z$5:$Z$312,②顧問先マスター!$E$5:$E$312,A24,②顧問先マスター!$L$5:$L$312,"中位60%") -> 0
A25: 越沼 浩美 | B25: =COUNTIFS(②顧問先マスター!$E$5:$E$312,A25,②顧問先マスター!$L$5:$L$312,"中位60%") -> 0 | C25: =SUMIFS(②顧問先マスター!$Z$5:$Z$312,②顧問先マスター!$E$5:$E$312,A25,②顧問先マスター!$L$5:$L$312,"中位60%") -> 0
A26: 福田 秀幸 | B26: =COUNTIFS(②顧問先マスター!$E$5:$E$312,A26,②顧問先マスター!$L$5:$L$312,"中位60%") -> 0 | C26: =SUMIFS(②顧問先マスター!$Z$5:$Z$312,②顧問先マスター!$E$5:$E$312,A26,②顧問先マスター!$L$5:$L$312,"中位60%") -> 0
A27: 田村 未帆 | B27: =COUNTIFS(②顧問先マスター!$E$5:$E$312,A27,②顧問先マスター!$L$5:$L$312,"中位60%") -> 0 | C27: =SUMIFS(②顧問先マスター!$Z$5:$Z$312,②顧問先マスター!$E$5:$E$312,A27,②顧問先マスター!$L$5:$L$312,"中位60%") -> 0
A28: 和田 小百合 | B28: =COUNTIFS(②顧問先マスター!$E$5:$E$312,A28,②顧問先マスター!$L$5:$L$312,"中位60%") -> 0 | C28: =SUMIFS(②顧問先マスター!$Z$5:$Z$312,②顧問先マスター!$E$5:$E$312,A28,②顧問先マスター!$L$5:$L$312,"中位60%") -> 0
A29: 南雲 拓也 | B29: =COUNTIFS(②顧問先マスター!$E$5:$E$312,A29,②顧問先マスター!$L$5:$L$312,"中位60%") -> 0 | C29: =SUMIFS(②顧問先マスター!$Z$5:$Z$312,②顧問先マスター!$E$5:$E$312,A29,②顧問先マスター!$L$5:$L$312,"中位60%") -> 0
A30: 深澤 優太 | B30: =COUNTIFS(②顧問先マスター!$E$5:$E$312,A30,②顧問先マスター!$L$5:$L$312,"中位60%") -> 0 | C30: =SUMIFS(②顧問先マスター!$Z$5:$Z$312,②顧問先マスター!$E$5:$E$312,A30,②顧問先マスター!$L$5:$L$312,"中位60%") -> 0
A31: 一場 明美 | B31: =COUNTIFS(②顧問先マスター!$E$5:$E$312,A31,②顧問先マスター!$L$5:$L$312,"中位60%") -> 0 | C31: =SUMIFS(②顧問先マスター!$Z$5:$Z$312,②顧問先マスター!$E$5:$E$312,A31,②顧問先マスター!$L$5:$L$312,"中位60%") -> 0
A32: 町田 尚史 | B32: =COUNTIFS(②顧問先マスター!$E$5:$E$312,A32,②顧問先マスター!$L$5:$L$312,"中位60%") -> 0 | C32: =SUMIFS(②顧問先マスター!$Z$5:$Z$312,②顧問先マスター!$E$5:$E$312,A32,②顧問先マスター!$L$5:$L$312,"中位60%") -> 0
... A35: 事務所共有１ | B35: =COUNTIFS(②顧問先マスター!$E$5:$E$312,A35,②顧問先マスター!$L$5:$L$312,"中位60%") -> 0 | C35: =SUMIFS(②顧問先マスター!$Z$5:$Z$312,②顧問先マスター!$E$5:$E$312,A35,②顧問先マスター!$L$5:$L$312,"中位60%") -> 0
A36: （担当未設定） | B36: =COUNTIFS(②顧問先マスター!$E$5:$E$312,"",②顧問先マスター!$L$5:$L$312,"中位60%") -> 0 | C36: =SUMIFS(②顧問先マスター!$Z$5:$Z$312,②顧問先マスター!$E$5:$E$312,"",②顧問先マスター!$L$5:$L$312,"中位60%") -> 0
A38: ■ ステータス別（中位60%）
A39: ステータス | B39: 件数
A40: 提案準備中 | B40: =COUNTIFS(②顧問先マスター!$AB$5:$AB$312,"提案準備中",②顧問先マスター!$L$5:$L$312,"中位60%") -> 0
A41: 提案済 | B41: =COUNTIFS(②顧問先マスター!$AB$5:$AB$312,"提案済",②顧問先マスター!$L$5:$L$312,"中位60%") -> 0
A42: 受注 | B42: =COUNTIFS(②顧問先マスター!$AB$5:$AB$312,"受注",②顧問先マスター!$L$5:$L$312,"中位60%") -> 0
A43: 見送り | B43: =COUNTIFS(②顧問先マスター!$AB$5:$AB$312,"見送り",②顧問先マスター!$L$5:$L$312,"中位60%") -> 0
